Workbook

Sheet Deckblatt

Sheet Impressum
A4: Impressum
A6: Produktlinie/Reihe: | B6: Tabellen
A8: Produkt-ID: | B8: 709
A10: Titel: | B10: Regionalreport über Beschäftigte (Quartalszahlen)
A12: Region: | B12: Görlitz (14626)
A14: Berichtsmonat: | B14: 30. Juni 2025
A16: Erstellungsdatum: | B16: 10.01.2026
A18: Periodizität: | B18: vierteljährlich
A20: Nächster Veröffentlichungstermin: | B20: 10.04.2026
A22: Hinweise: | B22: In dieser Publikation wird über die sozialversicherungspflichtig und geringfügig entlohnten Beschäftigten berichtet. Eine weitere Unterteilung der geringfügig entlohnten Beschäftigten in ausschließlich geringfügig entlohnte und im Nebenjob tätige Beschäftigte ist bei ausgewählten Merkmalen, wie dem Beruf, aus Geheimhaltungsgründen nicht möglich. Weitergehende Informationen erhalten Sie über Ihren regionalen Statistik-Service. Soweit nicht anders angegeben, beziehen sich alle Zahlen auf den Arbeitsort.
A25: Herausgeberin: | B25: Bundesagentur für Arbeit
B26: Statistik
A27: Rückfragen an: | B27: Statistik-Service Südost
B28: Nordostpark 14
B29: 90411 Nürnberg
A30: E-Mail: | B30: Statistik-Service-Suedost@arbeitsagentur.de
A31: Hotline: | B31: 0911/179-8001
A32: Fax: | B32: 0911/179-908001
A34: Internet: | B34: https://statistik.arbeitsagentur.de
A36: Zitierhinweis: | B36: Statistik der Bundesagentur für Arbeit,
B37: Tabellen, Regionalreport über Beschäftigte (Quartalszahlen), Nürnberg, Dezember 2025
A39: Nutzungsbedingungen: | B39: © Statistik der Bundesagentur für Arbeit
B40: Die Produkte unterliegen dem Urheberrecht (siehe Impressum).
B41: Daten und Tabellen dürfen uneingeschränkt verwendet werden. Informationen dürfen (auch auszugsweise) gespeichert und mit Quellenangabe weitergegeben, vervielfältigt und verbreitet werden. Die Inhalte dürfen nicht verändert oder verfälscht werden. Eigene Berechnungen sind erlaubt, jedoch als solche kenntlich zu machen. Im Fall einer Veröffentlichung im Internet soll dies mit einer Verlinkung auf die Homepage der Statistik der Bundesagentur für Arbeit erfolgen.

Sheet Inhaltsverzeichnis
G1: Beschäftigungsstatistik
A4: Inhaltsverzeichnis
A7: Regionalreport über Beschäftigte (Quartalszahlen)
A8: Görlitz (14626)
A9: Stichtag: 30. Juni 2025
A12: Quartalszahlen im Überblick
A13: Sozialversicherungspflichtig und geringfügig entlohnte Beschäftigte
B14: nach ausgewählten Merkmalen | G14: Tabelle 1
A15: Diagramm: Entwicklung sozialversicherungspflichtig Beschäftigter
B16: und geringfügig entlohnter Beschäftigter nach Regionen und nach
B17: der Klassifikation der Wirtschaftszweige (WZ 2008) | G17: Diagramm
A19: Sozialversicherungspflichtig Beschäftigte
B20: nach Regionen und ausgewählten Merkmalen | G20: Tabelle 2.1
B21: nach ausgewählten Merkmalen | G21: Tabelle 2.2
B22: nach der Klassifikation der Wirtschaftszweige 2008 (WZ 2008) | G22: Tabelle 2.3
B23: nach der Klassifikation der Berufe (KldB 2010) | G23: Tabelle 2.4
A25: Geringfügig entlohnte Beschäftigte
B26: nach Regionen und ausgewählten Merkmalen | G26: Tabelle 3.1
B27: nach ausgewählten Merkmalen | G27: Tabelle 3.2
B28: nach der Klassifikation der Wirtschaftszweige 2008 (WZ 2008) | G28: Tabelle 3.3
B29: nach der Klassifikation der Berufe (KldB 2010) | G29: Tabelle 3.4
A31: Begonnene sozialversicherungspflichtige Beschäftigungsverhältnisse
B32: Insgesamt / darunter befristet nach ausgewählten Merkmalen | G32: Tabelle 4.1
B33: nach der Klassifikation der Wirtschaftszweige 2008 (WZ 2008) | G33: Tabelle 4.2
B34: nach der Klassifikation der Berufe (KldB 2010) | G34: Tabelle 4.3
A36: Beendete sozialversicherungspflichtige Beschäftigungsverhältnisse
B37: nach der Klassifikation der Wirtschaftszweige 2008 (WZ 2008) | G37: Tabelle 5.1
B38: nach der Klassifikation der Berufe (KldB 2010) | G38: Tabelle 5.2
A40: Zeitreihe
B41: Sozialversicherungspflichtig und geringfügig entlohnte Beschäftigte sowie begonnene und beendete Beschäftigungsverhältnisse | G41: Tabelle 6
A43: Hinweisblätter
B45: Methodische Hinweise Berufsaggregate | G45: Hinw Berufsagg
B46: Methodische Hinweise Befristung | G46: Hinw Befristung
B47: Methodische Hinweise zu begonnenen und beendeten Beschäftigungsverhältnissen | G47: Hinw beg_been_BV
B48: Methodische Hinweise zu sozialversicherungspflichtig und geringfügig Beschäftigten | G48: Hinw SvB GB

Sheet Tabelle 1
J1: Beschäftigungsstatistik
A3: 1. Sozialversicherungspflichtig und geringfügig entlohnte Beschäftigte nach ausgewählten Merkmalen
A4: Görlitz (14626); Gebietsstand des jeweiligen Stichtags
A5: Stichtag: 30. Juni 2025
A7: Merkmale | C7: Anteile in % 1) | D7: Beschäftigte am Stichtag Ende ... | I7: Veränderung gegenüber dem Vorjahresstichtag (Sp. 1 zu Sp. 5)
D8: Jun. 25 | E8: Mrz. 25 | F8: Dez. 24 | G8: Sep. 24 | H8: Jun. 24
I9: absolut | J9: in %
D10: 1 | E10: 2 | F10: 3 | G10: 4 | H10: 5 | I10: 6 | J10: 7
A11: Sozialversicherungspflichtig Beschäftigte
A12: Insgesamt | C12: 100 | D12: 87540 | E12: 87355 | F12: 88337 | G12: 89302 | H12: 88265 | I12: -725 | J12: -0.82139013
A13: dav. | B13: Männer | C13: 49.830934 | D13: 43622 | E13: 43343 | F13: 43830 | G13: 44432 | H13: 43837 | I13: -215 | J13: -0.49045327
B14: Frauen | C14: 50.169066 | D14: 43918 | E14: 44012 | F14: 44507 | G14: 44870 | H14: 44428 | I14: -510 | J14: -1.1479247
A15: dav. | B15: unter 25 Jahre | C15: 8.6737491 | D15: 7593 | E15: 7766 | F15: 8019 | G15: 8270 | H15: 7405 | I15: 188 | J15: 2.5388251
B16: 25 bis unter 55 Jahre | C16: 63.724012 | D16: 55784 | E16: 55706 | F16: 56108 | G16: 56667 | H16: 56426 | I16: -642 | J16: -1.1377734
B17: 55 bis unter 65 Jahre | C17: 25.980123 | D17: 22743 | E17: 22529 | F17: 22844 | G17: 23034 | H17: 23160 | I17: -417 | J17: -1.8005181
B18: 65 Jahre und älter | C18: 1.6221156 | D18: 1420 | E18: 1354 | F18: 1366 | G18: 1331 | H18: 1274 | I18: 146 | J18: 11.459969
B19: dar.: bis zur Altersgrenze | C19: 0.74251771 | D19: 650 | E19: 620 | F19: 579 | G19: 580 | H19: 555 | I19: 95 | J19: 17.117117
A20: dar. | B20: Vollzeitbeschäftigte | C20: 61.204021 | D20: 53578 | E20: 53667 | F20: 54374 | G20: 55180 | H20: 54570 | I20: -992 | J20: -1.8178486
B21: Teilzeitbeschäftigte | C21: 38.795979 | D21: 33962 | E21: 33688 | F21: 33963 | G21: 34122 | H21: 33695 | I21: 267 | J21: 0.79240243
A22: dar. | B22: Deutsche | C22: 86.801462 | D22: 75986 | E22: 76125 | F22: 77226 | G22: 77999 | H22: 77271 | I22: -1285 | J22: -1.6629783
B23: Ausländer | C23: 13.198538 | D23: 11554 | E23: 11230 | F23: 11111 | G23: 11303 | H23: 10994 | I23: 560 | J23: 5.0936875
A24: Geringfügig entlohnte Beschäftigte (GeB)
A25: GeB - Insgesamt
A26: Insgesamt | C26: 100 | D26: 11635 | E26: 11201 | F26: 11370 | G26: 11401 | H26: 11352 | I26: 283 | J26: 2.4929528
A27: dav. | B27: Männer | C27: 43.824667 | D27: 5099 | E27: 4899 | F27: 4922 | G27: 4931 | H27: 4926 | I27: 173 | J27: 3.5119773
B28: Frauen | C28: 56.175333 | D28: 6536 | E28: 6302 | F28: 6448 | G28: 6470 | H28: 6426 | I28: 110 | J28: 1.7117958
A29: dav. | B29: unter 25 Jahre | C29: 14.937688 | D29: 1738 | E29: 1471 | F29: 1483 | G29: 1532 | H29: 1608 | I29: 130 | J29: 8.0845771
B30: 25 bis unter 55 Jahre | C30: 36.106575 | D30: 4201 | E30: 4139 | F30: 4214 | G30: 4175 | H30: 4107 | I30: 94 | J30: 2.2887753
B31: 55 bis unter 65 Jahre | C31: 20.232058 | D31: 2354 | E31: 2364 | F31: 2391 | G31: 2418 | H31: 2437 | I31: -83 | J31: -3.4058268
B32: 65 Jahre und älter | C32: 28.723679 | D32: 3342 | E32: 3227 | F32: 3282 | G32: 3276 | H32: 3200 | I32: 142 | J32: 4.4375
B33: dar.: bis zur Altersgrenze | C33: 4.9505801 | D33: 576 | E33: 540 | F33: 500 | G33: 481 | H33: 464 | I33: 112 | J33: 24.137931
A34: dar. | B34: Deutsche | C34: 90.588741 | D34: 10540 | E34: 10189 | F34: 10354 | G34: 10345 | H34: 10328 | I34: 212 | J34: 2.0526723
B35: Ausländer | C35: 9.4112591 | D35: 1095 | E35: 1012 | F35: 1016 | G35: 1056 | H35: 1024 | I35: 71 | J35: 6.9335938
A36: GeB - ausschließlich
A37: Insgesamt | C37: 100 | D37: 7885 | E37: 7546 | F37: 7625 | G37: 7668 | H37: 7760 | I37: 125 | J37: 1.6108247
A38: dav. | B38: Männer | C38: 45.732403 | D38: 3606 | E38: 3457 | F38: 3445 | G38: 3454 | H38: 3508 | I38: 98 | J38: 2.7936146
B39: Frauen | C39: 54.267597 | D39: 4279 | E39: 4089 | F39: 4180 | G39: 4214 | H39: 4252 | I39: 27 | J39: 0.6349953
A40: dav. | B40: unter 25 Jahre | C40: 17.577679 | D40: 1386 | E40: 1133 | F40: 1123 | G40: 1140 | H40: 1266 | I40: 120 | J40: 9.478673
B41: 25 bis unter 55 Jahre | C41: 21.382372 | D41: 1686 | E41: 1678 | F41: 1704 | G41: 1715 | H41: 1738 | I41: -52 | J41: -2.9919448
B42: 55 bis unter 65 Jahre | C42: 19.695625 | D42: 1553 | E42: 1586 | F42: 1593 | G42: 1606 | H42: 1626 | I42: -73 | J42: -4.4895449
...

Sheet Diagramm
I1: Beschäftigungsstatistik
A3: Entwicklung sozialversicherungspflichtig Beschäftigter und geringfügig entlohnter Beschäftigter nach Regionen
A4: und nach der Klassifikation der Wirtschaftszweige 2008 (WZ 2008)
A5: ausgewählte Regionen; Gebietsstand des jeweiligen Stichtags
A6: Stichtag: 30. Juni 2025 | D6: Veränderung gegenüber dem Vorjahresstichtag in %
D7: Sozialversicherungspflichtig Beschäftigte | G7: Geringfügig entlohnte Beschäftigte (insgesamt)
A9: Görlitz (14626)
A10: Bundesland Sachsen
A11: Ostdeutschland
A12: Deutschland
A15: Görlitz (14626)
A16: Insgesamt
A17: A | B17: Land-, Forstwirtschaft und Fischerei
A18: B,D,E | B18: Bergbau, Energie- und Wasserversorgung, Energiewirtschaft
A19: C dav. | B19: Verarbeitendes Gewerbe
A20: 10-15, 18, 21, 31 | B20: Herstellung von überwiegend häuslich konsumierten Gütern (ohne Güter der Metall-, Elektro- und Chemieindustrie)
A21: 24-30,32,33 | B21: Metall- und Elektroindustrie sowie Stahlindustrie
A22: 16, 17, 19, 20, ,22, 23 | B22: Hrst. v. Vorleistungsgütern, insb. v. chem. Erzeugnissen u. Kunsstoffwaren (ohne Güter der Metall- u. Elektroindustrie)
A23: F | B23: Baugewerbe
A24: G | B24: Handel, Instandhaltung, Reparatur von Kfz
A25: H | B25: Verkehr und Lagerei
A26: I | B26: Gastgewerbe
A27: J | B27: Information und Kommunikation
A28: K | B28: Erbringung von Finanz- und Versicherungsdienstleistungen
... A31: dav. N (ohne ANÜ | B31: sonstige wirtschaftliche Dienstleistungen (ohne Arbeitnehmerüberlassung)
A32: 782.783 | B32: Arbeitnehmerüberlassung
A33: O, U | B33: Öffentliche Verwaltung, Verteidigung, Sozialversicherung, Ext. Organisationen
A34: P | B34: Erziehung und Unterricht
A35: 86 | B35: Gesundheitswesen
A36: 87.88 | B36: Heime und Sozialwesen
A37: R,S,T | B37: sonstige Dienstleistungen, Private Haushalte
B38: keine Zuordnung möglich
A39: davon nach Sektoren:
A40: A | B40: Land-, Forstwirtschaft und Fischerei
A41: B - F | B41: Produzierendes Gewerbe
A42: G - U | B42: Dienstleistungsbereich
I44: © Statistik der Bundesagentur für Arbeit
A45: *) Aus Datenschutzgründen und Gründen der statistischen Geheimhaltung werden Zahlenwerte von 1 oder 2 und Daten, aus denen rechnerisch auf einen solchen Zahlenwert geschlossen werden kann, anonymisiert. Gleiches gilt, wenn in einer Region weniger als 3 Betriebe ansässig sind oder einer der Betriebe einen so hohen Beschäftigtenanteil auf sich vereint, dass die Beschäftigtenzahl praktisch eine Einzelangabe über den Branchenführer darstellt (Dominanzfall).

Sheet Tabelle 2.1
J1: Beschäftigungsstatistik
A3: 2.1 Sozialversicherungspflichtig Beschäftigte nach Regionen und ausgewählten Merkmalen
A4: ausgewählte Regionen; Gebietsstand des jeweiligen Stichtags
A5: Stichtag: 30. Juni 2025
A7: Regionen / Merkmale | C7: Anteile in % 1) | D7: sozialversicherungspflichtig Beschäftigte am Stichtag Ende ... | I7: Veränderung gegenüber dem Vorjahresstichtag (Spalte 1 zu Spalte 5)
D8: Jun. 25 | E8: Mrz. 25 | F8: Dez. 24 | G8: Sep. 24 | H8: Jun. 24
I9: absolut | J9: in %
D10: 1 | E10: 2 | F10: 3 | G10: 4 | H10: 5 | I10: 6 | J10: 7
A11: Görlitz (14626)
A12: Insgesamt | C12: 100 | D12: 87540 | E12: 87355 | F12: 88337 | G12: 89302 | H12: 88265 | I12: -725 | J12: -0.82139013
A13: dav. | B13: Männer | C13: 49.830934 | D13: 43622 | E13: 43343 | F13: 43830 | G13: 44432 | H13: 43837 | I13: -215 | J13: -0.49045327
B14: Frauen | C14: 50.169066 | D14: 43918 | E14: 44012 | F14: 44507 | G14: 44870 | H14: 44428 | I14: -510 | J14: -1.1479247
A15: dav. | B15: unter 25 Jahre | C15: 8.6737491 | D15: 7593 | E15: 7766 | F15: 8019 | G15: 8270 | H15: 7405 | I15: 188 | J15: 2.5388251
B16: 25 bis unter 55 Jahre | C16: 63.724012 | D16: 55784 | E16: 55706 | F16: 56108 | G16: 56667 | H16: 56426 | I16: -642 | J16: -1.1377734
B17: 55 bis unter 65 Jahre | C17: 25.980123 | D17: 22743 | E17: 22529 | F17: 22844 | G17: 23034 | H17: 23160 | I17: -417 | J17: -1.8005181
B18: 65 Jahre und älter | C18: 1.6221156 | D18: 1420 | E18: 1354 | F18: 1366 | G18: 1331 | H18: 1274 | I18: 146 | J18: 11.459969
B19: dar.: bis zur Altersgrenze | C19: 0.74251771 | D19: 650 | E19: 620 | F19: 579 | G19: 580 | H19: 555 | I19: 95 | J19: 17.117117
A20: dar. | B20: in Vollzeit | C20: 61.204021 | D20: 53578 | E20: 53667 | F20: 54374 | G20: 55180 | H20: 54570 | I20: -992 | J20: -1.8178486
B21: in Teilzeit | C21: 38.795979 | D21: 33962 | E21: 33688 | F21: 33963 | G21: 34122 | H21: 33695 | I21: 267 | J21: 0.79240243
A22: dar. | B22: Deutsche | C22: 86.801462 | D22: 75986 | E22: 76125 | F22: 77226 | G22: 77999 | H22: 77271 | I22: -1285 | J22: -1.6629783
B23: Ausländer | C23: 13.198538 | D23: 11554 | E23: 11230 | F23: 11111 | G23: 11303 | H23: 10994 | I23: 560 | J23: 5.0936875
A24: Bundesland Sachsen
A25: Insgesamt | C25: 100 | D25: 1625455 | E25: 1629818 | F25: 1644126 | G25: 1656291 | H25: 1637894 | I25: -12439 | J25: -0.75945086
A26: dav. | B26: Männer | C26: 52.274471 | D26: 849698 | E26: 850625 | F26: 857604 | G26: 865693 | H26: 855211 | I26: -5513 | J26: -0.64463624
B27: Frauen | C27: 47.725529 | D27: 775757 | E27: 779193 | F27: 786522 | G27: 790598 | H27: 782683 | I27: -6926 | J27: -0.88490487
A28: dav. | B28: unter 25 Jahre | C28: 9.2745108 | D28: 150753 | E28: 155241 | F28: 161295 | G28: 164699 | H28: 149591 | I28: 1162 | J28: 0.7767847
B29: 25 bis unter 55 Jahre | C29: 65.67761 | D29: 1067560 | E29: 1069926 | F29: 1074923 | G29: 1082667 | H29: 1079658 | I29: -12098 | J29: -1.12054
B30: 55 bis unter 65 Jahre | C30: 23.443097 | D30: 381057 | E30: 379539 | F30: 382668 | G30: 384574 | H30: 385142 | I30: -4085 | J30: -1.0606478
B31: 65 Jahre und älter | C31: 1.6047814 | D31: 26085 | E31: 25112 | F31: 25240 | G31: 24351 | H31: 23503 | I31: 2582 | J31: 10.985832
B32: dar.: bis zur Altersgrenze | C32: 0.72318212 | D32: 11755 | E32: 11433 | F32: 10331 | G32: 10075 | H32: 9619 | I32: 2136 | J32: 22.206051
A33: dar. | B33: in Vollzeit | C33: 65.012566 | D33: 1056750 | E33: 1063271 | F33: 1075496 | G33: 1087830 | H33: 1077220 | I33: -20470 | J33: -1.9002618
B34: in Teilzeit | C34: 34.987373 | D34: 568704 | E34: 566546 | F34: 568629 | G34: 568461 | H34: 560674 | I34: 8030 | J34: 1.4322048
A35: dar. | B35: Deutsche | C35: 90.709001 | D35: 1474434 | E35: 1481948 | F35: 1498132 | G35: 1510135 | H35: 1496357 | I35: -21923 | J35: -1.4650916
B36: Ausländer | C36: 9.2909985 | D36: 151021 | E36: 147870 | F36: 145994 | G36: 146156 | H36: 141537 | I36: 9484 | J36: 6.7007214
A37: Ostdeutschland
A38: Insgesamt | C38: 100 | D38: 6340446 | E38: 6340342 | F38: 6382895 | G38: 6422497 | H38: 6368681 | I38: -28235 | J38: -0.44334141
A39: dav. | B39: Männer | C39: 51.814462 | D39: 3285268 | E39: 3278664 | F39: 3298170 | G39: 3324450 | H39: 3290619 | I39: -5351 | J39: -0.16261378
B40: Frauen | C40: 48.185538 | D40: 3055178 | E40: 3061678 | F40: 3084725 | G40: 3098047 | H40: 3078062 | I40: -22884 | J40: -0.74345481
A41: dav. | B41: unter 25 Jahre | C41: 9.0634634 | D41: 574664 | E41: 587278 | F41: 608061 | G41: 617036 | H41: 567979 | I41: 6685 | J41: 1.1769801
B42: 25 bis unter 55 Jahre | C42: 66.233732 | D42: 4199514 | E42: 4196176 | F42: 4207636 | G42: 4233356 | H42: 4228677 | I42: -29163 | J42: -0.68964832
...

Sheet Tabelle 2.2
L1: Beschäftigungsstatistik
A3: 2.2 Sozialversicherungspflichtig Beschäftigte nach ausgewählten Merkmalen
A4: Görlitz (14626); Gebietsstand des jeweiligen Stichtags
A5: Stichtag: 30. Juni 2025
A7: Merkmale | E7: Anteile in % 1) | F7: sozialversicherungspflichtig Beschäftigte am Stichtag Ende ... | K7: Veränderung gegenüber dem Vorjahresstichtag (Spalte 1 zu Spalte 5)
F8: Jun. 25 | G8: Mrz. 25 | H8: Dez. 24 | I8: Sep. 24 | J8: Jun. 24
K9: absolut | L9: in %
F10: 1 | G10: 2 | H10: 3 | I10: 4 | J10: 5 | K10: 6 | L10: 7
A11: Insgesamt | E11: 100 | F11: 87540 | G11: 87355 | H11: 88337 | I11: 89302 | J11: 88265 | K11: -725 | L11: -0.82139013
A12: nach dem Geschlecht dav. Männer | E12: 49.830934 | F12: 43622 | G12: 43343 | H12: 43830 | I12: 44432 | J12: 43837 | K12: -215 | L12: -0.49045327
B13: Frauen | E13: 50.169066 | F13: 43918 | G13: 44012 | H13: 44507 | I13: 44870 | J13: 44428 | K13: -510 | L13: -1.1479247
A14: nach Altersgruppen und Geschlecht dav. unter 25 Jahre | E14: 8.6737491 | F14: 7593 | G14: 7766 | H14: 8019 | I14: 8270 | J14: 7405 | K14: 188 | L14: 2.5388251
C15: Männer | E15: 57.605689 | F15: 4374 | G15: 4444 | H15: 4599 | I15: 4759 | J15: 4276 | K15: 98 | L15: 2.2918616
C16: Frauen | E16: 42.394311 | F16: 3219 | G16: 3322 | H16: 3420 | I16: 3511 | J16: 3129 | K16: 90 | L16: 2.8763183
B17: 25 bis unter 55 Jahre | E17: 63.724012 | F17: 55784 | G17: 55706 | H17: 56108 | I17: 56667 | J17: 56426 | K17: -642 | L17: -1.1377734
C18: Männer | E18: 50.589775 | F18: 28221 | G18: 28064 | H18: 28279 | I18: 28613 | J18: 28482 | K18: -261 | L18: -0.91636823
C19: Frauen | E19: 49.410225 | F19: 27563 | G19: 27642 | H19: 27829 | I19: 28054 | J19: 27944 | K19: -381 | L19: -1.3634412
B20: 55 bis unter 65 Jahre | E20: 25.980123 | F20: 22743 | G20: 22529 | H20: 22844 | I20: 23034 | J20: 23160 | K20: -417 | L20: -1.8005181
C21: Männer | E21: 45.306248 | F21: 10304 | G21: 10152 | H21: 10248 | I21: 10359 | J21: 10412 | K21: -108 | L21: -1.0372647
C22: Frauen | E22: 54.693752 | F22: 12439 | G22: 12377 | H22: 12596 | I22: 12675 | J22: 12748 | K22: -309 | L22: -2.4239096
B23: 65 Jahre und älter | E23: 1.6221156 | F23: 1420 | G23: 1354 | H23: 1366 | I23: 1331 | J23: 1274 | K23: 146 | L23: 11.459969
C24: Männer | E24: 50.915493 | F24: 723 | G24: 683 | H24: 704 | I24: 701 | J24: 667 | K24: 56 | L24: 8.3958021
C25: Frauen | E25: 49.084507 | F25: 697 | G25: 671 | H25: 662 | I25: 630 | J25: 607 | K25: 90 | L25: 14.827018
C26: dar. | D26: bis zur Altersgrenze | E26: 0.74251771 | F26: 650 | G26: 620 | H26: 579 | I26: 580 | J26: 555 | K26: 95 | L26: 17.117117
D27: Männer | E27: 46 | F27: 299 | G27: 290 | H27: 292 | I27: 291 | J27: 265 | K27: 34 | L27: 12.830189
D28: Frauen | E28: 54 | F28: 351 | G28: 330 | H28: 287 | I28: 289 | J28: 290 | K28: 61 | L28: 21.034483
A29: nach Nationalität und Geschlecht dar. Deutsche | E29: 86.801462 | F29: 75986 | G29: 76125 | H29: 77226 | I29: 77999 | J29: 77271 | K29: -1285 | L29: -1.6629783
C30: Männer | E30: 48.955071 | F30: 37199 | G30: 37096 | H30: 37653 | I30: 38108 | J30: 37666 | K30: -467 | L30: -1.239845
C31: Frauen | E31: 51.044929 | F31: 38787 | G31: 39029 | H31: 39573 | I31: 39891 | J31: 39605 | K31: -818 | L31: -2.0653958
B32: Ausländer | E32: 13.198538 | F32: 11554 | G32: 11230 | H32: 11111 | I32: 11303 | J32: 10994 | K32: 560 | L32: 5.0936875
C33: Männer | E33: 55.591137 | F33: 6423 | G33: 6247 | H33: 6177 | I33: 6324 | J33: 6171 | K33: 252 | L33: 4.0836169
C34: Frauen | E34: 44.408863 | F34: 5131 | G34: 4983 | H34: 4934 | I34: 4979 | J34: 4823 | K34: 308 | L34: 6.3860668
A35: nach der Arbeitszeit und Geschlecht dar. in Vollzeit | E35: 61.204021 | F35: 53578 | G35: 53667 | H35: 54374 | I35: 55180 | J35: 54570 | K35: -992 | L35: -1.8178486
C36: Männer | E36: 67.251484 | F36: 36032 | G36: 35960 | H36: 36416 | I36: 36981 | J36: 36507 | K36: -475 | L36: -1.3011203
C37: Frauen | E37: 32.748516 | F37: 17546 | G37: 17707 | H37: 17958 | I37: 18199 | J37: 18063 | K37: -517 | L37: -2.8622045
B38: in Teilzeit | E38: 38.795979 | F38: 33962 | G38: 33688 | H38: 33963 | I38: 34122 | J38: 33695 | K38: 267 | L38: 0.79240243
C39: Männer | E39: 22.348507 | F39: 7590 | G39: 7383 | H39: 7414 | I39: 7451 | J39: 7330 | K39: 260 | L39: 3.5470668
C40: Frauen | E40: 77.651493 | F40: 26372 | G40: 26305 | H40: 26549 | I40: 26671 | J40: 26365 | K40: 7 | L40: 0.026550351
A41: Auszubildende nach Geschlecht Auszubildende | E41: 3.3241947 | F41: 2910 | G41: 3119 | H41: 3407 | I41: 3468 | J41: 2856 | K41: 54 | L41: 1.8907563
C42: Männer | E42: 58.522337 | F42: 1703 | G42: 1829 | H42: 2054 | I42: 2080 | J42: 1696 | K42: 7 | L42: 0.41273585
...

Sheet Tabelle 2.3
J1: Beschäftigungsstatistik
A3: 2.3 Sozialversicherungspflichtig Beschäftigte nach der Klassifikation der Wirtschaftszweige 2008 (WZ 2008)
A4: Görlitz (14626); Gebietsstand des jeweiligen Stichtags
A5: Stichtag: 30. Juni 2025
A7: Wirtschaftsabschnitte / Wirtschaftsabteilungen / Wirtschaftsgruppen WZ 2008 | C7: Anteile in % 1) | D7: sozialversicherungspflichtig Beschäftigte am Stichtag Ende ... | I7: Veränderung gegenüber dem Vorjahresstichtag (Spalte 1 zu Spalte 5)
D8: Jun. 25 | E8: Mrz. 25 | F8: Dez. 24 | G8: Sep. 24 | H8: Jun. 24
I9: absolut | J9: in %
D10: 1 | E10: 2 | F10: 3 | G10: 4 | H10: 5 | I10: 6 | J10: 7
A11: Insgesamt | C11: 100 | D11: 87540 | E11: 87355 | F11: 88337 | G11: 89302 | H11: 88265 | I11: -725 | J11: -0.82139013
A12: A | B12: Land-, Forstwirtschaft und Fischerei | C12: 1.8585789 | D12: 1627 | E12: 1607 | F12: 1585 | G12: 1679 | H12: 1646 | I12: -19 | J12: -1.1543135
A13: B,D,E | B13: Bergbau, Energie- und Wasserversorgung, Entsorgungswirtschaft | C13: 3.3139136 | D13: 2901 | E13: 2890 | F13: 2910 | G13: 2950 | H13: 2959 | I13: -58 | J13: -1.9601217
A14: C | B14: Verarbeitendes Gewerbe | C14: 22.377199 | D14: 19589 | E14: 19584 | F14: 19652 | G14: 19850 | H14: 19659 | I14: -70 | J14: -0.35607101
A15: dav. 10-15, 18, 21, 31 | B15: Herstellung von überwiegend häuslich konsumierten Gütern (ohne Güter der Metall-, Elektro- und Chemieindustrie) | C15: 7.8398446 | D15: 6863 | E15: 6803 | F15: 6738 | G15: 6800 | H15: 6779 | I15: 84 | J15: 1.2391208
A16: 24-30, 32, 33 | B16: Metall- und Elektroindustrie sowie Stahlindustrie | C16: 10.636281 | D16: 9311 | E16: 9358 | F16: 9428 | G16: 9486 | H16: 9393 | I16: -82 | J16: -0.87299052
A17: 16, 17, 19, 20, 22, 23 | B17: Hrst. v. Vorleistungsgütern, insb. v. chem. Erzeugnissen u. Kunststoffwaren (ohne Güter der Metall- u. Elektroindustrie) | C17: 3.9010738 | D17: 3415 | E17: 3423 | F17: 3486 | G17: 3564 | H17: 3487 | I17: -72 | J17: -2.0648122
A18: F | B18: Baugewerbe | C18: 6.4747544 | D18: 5668 | E18: 5610 | F18: 5739 | G18: 5893 | H18: 5817 | I18: -149 | J18: -2.5614578
A19: G | B19: Handel, Instandhaltung, Reparatur von Kfz | C19: 11.127485 | D19: 9741 | E19: 9819 | F19: 9994 | G19: 10143 | H19: 10027 | I19: -286 | J19: -2.8522988
A20: H | B20: Verkehr und Lagerei | C20: 3.3801691 | D20: 2959 | E20: 2990 | F20: 3073 | G20: 3102 | H20: 3144 | I20: -185 | J20: -5.8842239
A21: I | B21: Gastgewerbe | C21: 3.1973955 | D21: 2799 | E21: 2648 | F21: 2772 | G21: 2912 | H21: 2858 | I21: -59 | J21: -2.0643807
A22: J | B22: Information und Kommunikation | C22: 0.88873658 | D22: 778 | E22: 783 | F22: 807 | G22: 818 | H22: 817 | I22: -39 | J22: -4.7735618
A23: K | B23: Erbringung von Finanz- und Versicherungsdienstleistungen | C23: 1.1411926 | D23: 999 | E23: 989 | F23: 994 | G23: 988 | H23: 974 | I23: 25 | J23: 2.5667351
... A26: dav. N (ohne ANÜ) | B26: sonstige wirtschaftliche Dienstleistungen (ohne Arbeitnehmerüberlassung) | C26: 4.0735664 | D26: 3566 | E26: 3453 | F26: 3539 | G26: 3574 | H26: 3572 | I26: -6 | J26: -0.16797312
A27: 782.783 | B27: Arbeitnehmerüberlassung | C27: 0.66826594 | D27: 585 | E27: 595 | F27: 659 | G27: 704 | H27: 626 | I27: -41 | J27: -6.5495208
A28: O, U | B28: Öffentliche Verwaltung, Verteidigung, Sozialversicherung, Ext. Organisationen | C28: 7.0436372 | D28: 6166 | E28: 6157 | F28: 6233 | G28: 6241 | H28: 6203 | I28: -37 | J28: -0.59648557
A29: P | B29: Erziehung und Unterricht | C29: 4.3317341 | D29: 3792 | E29: 3856 | F29: 3887 | G29: 3828 | H29: 3821 | I29: -29 | J29: -0.75896362
A30: 86 | B30: Gesundheitswesen | C30: 8.2465159 | D30: 7219 | E30: 7285 | F30: 7320 | G30: 7347 | H30: 7152 | I30: 67 | J30: 0.93680089
A31: 87.88 | B31: Heime und Sozialwesen | C31: 12.679918 | D31: 11100 | E31: 11086 | F31: 11055 | G31: 10654 | H31: 10500 | I31: 600 | J31: 5.7142857
A32: R,S,T | B32: sonstige Dienstleistungen, Private Haushalte | C32: 4.2586246 | D32: 3728 | E32: 3709 | F32: 3775 | G32: 3822 | H32: 3728 | I32: 0 | J32: 0
B33: keine Zuordnung möglich | C33: 0 | D33: 0 | E33: 0 | F33: 0 | G33: 0 | H33: 0 | I33: 0 | J33: 0
A34: davon nach Sektoren:
A35: A | B35: Land-, Forstwirtschaft und Fischerei | C35: 1.8585789 | D35: 1627 | E35: 1607 | F35: 1585 | G35: 1679 | H35: 1646 | I35: -19 | J35: -1.1543135
A36: B - F | B36: Produzierendes Gewerbe | C36: 32.165867 | D36: 28158 | E36: 28084 | F36: 28301 | G36: 28693 | H36: 28435 | I36: -277 | J36: -0.97415157
A37: G - U | B37: Dienstleistungsbereich | C37: 65.975554 | D37: 57755 | E37: 57664 | F37: 58451 | G37: 58930 | H37: 58184 | I37: -429 | J37: -0.7373161
J38: © Statistik der Bundesagentur für Arbeit
A39: 1) Anteil an der jeweiligen Gesamtsumme (Spaltenprozent)
A40: *) Aus Datenschutzgründen und Gründen der statistischen Geheimhaltung werden Zahlenwerte von 1 oder 2 und Daten, aus denen rechnerisch auf einen solchen Zahlenwert geschlossen werden kann, anonymisiert. Gleiches gilt, wenn in einer Region weniger als 3 Betriebe ansässig sind oder einer der Betriebe einen so hohen Beschäftigtenanteil auf sich vereint, dass die Beschäftigtenzahl praktisch eine Einzelangabe über den Branchenführer darstellt (Dominanzfall).

Sheet Tabelle 2.4
K1: Beschäftigungsstatistik
A3: 2.4 Sozialversicherungspflichtig Beschäftigte nach der Klassifikation der Berufe (KldB 2010)
A4: Görlitz (14626); Gebietsstand des jeweiligen Stichtags
A5: Stichtag: 30. Juni 2025
A7: Anforderungsniveau/ Berufshauptgruppen/-gruppen (KldB2010) | D7: Anteile in % 1) | E7: sozialversicherungspflichtig Beschäftigte am Stichtag Ende ... | J7: Veränderung gegenüber dem Vorjahresstichtag (Spalte 1 zu Spalte 5)
E8: Jun. 25 | F8: Mrz. 25 | G8: Dez. 24 | H8: Sep. 24 | I8: Jun. 24
J9: absolut | K9: in %
E10: 1 | F10: 2 | G10: 3 | H10: 4 | I10: 5 | J10: 6 | K10: 7
A11: Insgesamt | D11: 100 | E11: 87540 | F11: 87355 | G11: 88337 | H11: 89302 | I11: 88265 | J11: -725 | K11: -0.82139013
A12: darunter nach Anforderungsniveau der ausgeübten Tätigkeit (KldB 2010)
A13: Helfer | D13: 16.446196 | E13: 14397 | F13: 14093 | G13: 14124 | H13: 14335 | I13: 14209 | J13: 188 | K13: 1.3231051
A14: Fachkraft | D14: 61.545579 | E14: 53877 | F14: 53970 | G14: 54801 | H14: 55562 | I14: 54810 | J14: -933 | K14: -1.7022441
A15: Spezialist | D15: 10.877313 | E15: 9522 | F15: 9494 | G15: 9488 | H15: 9506 | I15: 9421 | J15: 101 | K15: 1.072073
A16: Experte | D16: 10.235321 | E16: 8960 | F16: 9012 | G16: 9130 | H16: 9102 | I16: 9040 | J16: -80 | K16: -0.88495575
A17: darunter: ausgewählte Berufsaggregate2) nach der ausgeübten Tätigkeit (KldB 2010)
A18: Bauberufe | D18: 6.3399589 | E18: 5550 | F18: 5470 | G18: 5633 | H18: 5817 | I18: 5713 | J18: -163 | K18: -2.853142
A19: Handwerksberufe | D19: 16.028101 | E19: 14031 | F19: 13949 | G19: 14208 | H19: 14439 | I19: 14244 | J19: -213 | K19: -1.4953665
A20: Ingenieure | D20: 1.6552433 | E20: 1449 | F20: 1442 | G20: 1461 | H20: 1459 | I20: 1444 | J20: 5 | K20: 0.34626039
A21: MINT-Berufe | D21: 19.944026 | E21: 17459 | F21: 17466 | G21: 17709 | H21: 17888 | I21: 17662 | J21: -203 | K21: -1.1493602
A22: Pflegeberufe3) | D22: 9.0370117 | E22: 7911 | F22: 7926 | G22: 7989 | H22: 7998 | I22: 7890 | J22: 21 | K22: 0.2661597
A23: davon nach Berufsfachlichkeit der ausgeübten Tätigkeit (KldB 2010)
A24: 11 | B24: Land-, Tier-, Forstwirtschaftsberufe | D24: 1.6118346 | E24: 1411 | F24: 1399 | G24: 1404 | H24: 1456 | I24: 1414 | J24: -3 | K24: -0.21216407
A25: dar. 111 | B25: Landwirtschaft | D25: 0.84304318 | E25: 738 | F25: 718 | G25: 708 | H25: 750 | I25: 732 | J25: 6 | K25: 0.81967213
A26: 12 | B26: Gartenbauberufe, Floristik | D26: 0.7356637 | E26: 644 | F26: 606 | G26: 592 | H26: 657 | I26: 660 | J26: -16 | K26: -2.4242424
A27: 21 | B27: Rohstoffgewinn,Glas-,Keramikverarbeitung | D27: 1.2988348 | E27: 1137 | F27: 1137 | G27: 1135 | H27: 1154 | I27: 1133 | J27: 4 | K27: 0.35304501
A28: 22 | B28: Kunststoff- u. Holzherst.,-verarbeitung | D28: 2.2743889 | E28: 1991 | F28: 1994 | G28: 2011 | H28: 2047 | I28: 2051 | J28: -60 | K28: -2.9254022
A29: 23 | B29: Papier-,Druckberufe, tech.Mediengestalt. | D29: 0.37811286 | E29: 331 | F29: 340 | G29: 340 | H29: 345 | I29: 339 | J29: -8 | K29: -2.359882
A30: 24 | B30: Metallerzeugung,-bearbeitung, Metallbau | D30: 4.3877085 | E30: 3841 | F30: 3858 | G30: 3890 | H30: 3956 | I30: 3895 | J30: -54 | K30: -1.3863928
A31: 25 | B31: Maschinen- und Fahrzeugtechnikberufe | D31: 4.0998401 | E31: 3589 | F31: 3598 | G31: 3651 | H31: 3689 | I31: 3570 | J31: 19 | K31: 0.53221289
A32: 26 | B32: Mechatronik-, Energie- u. Elektroberufe | D32: 3.4315741 | E32: 3004 | F32: 3001 | G32: 3068 | H32: 3115 | I32: 3095 | J32: -91 | K32: -2.9402262
A33: 27 | B33: Techn.Entwickl.Konstr.Produktionssteuer. | D33: 2.2389765 | E33: 1960 | F33: 1981 | G33: 2004 | H33: 2010 | I33: 2011 | J33: -51 | K33: -2.5360517
A34: 28 | B34: Textil- und Lederberufe | D34: 3.4304318 | E34: 3003 | F34: 2990 | G34: 3034 | H34: 3059 | I34: 3059 | J34: -56 | K34: -1.8306636
A35: 29 | B35: Lebensmittelherstellung u. -verarbeitung | D35: 3.5046836 | E35: 3068 | F35: 3024 | G35: 2893 | H35: 2976 | I35: 2959 | J35: 109 | K35: 3.6836769
A36: dar. 292 | B36: Lebensmittel- u. Genussmittelherstellung | D36: 1.6049806 | E36: 1405 | F36: 1394 | G36: 1246 | H36: 1300 | I36: 1302 | J36: 103 | K36: 7.9109063
A37: dar. 293 | B37: Speisenzubereitung | D37: 1.8197395 | E37: 1593 | F37: 1558 | G37: 1576 | H37: 1602 | I37: 1583 | J37: 10 | K37: 0.63171194
A38: 31 | B38: Bauplanung,Architektur,Vermessungsberufe | D38: 0.58601782 | E38: 513 | F38: 507 | G38: 518 | H38: 514 | I38: 497 | J38: 16 | K38: 3.2193159
A39: 32 | B39: Hoch- und Tiefbauberufe | D39: 2.6342244 | E39: 2306 | F39: 2275 | G39: 2337 | H39: 2433 | I39: 2379 | J39: -73 | K39: -3.0685162
A40: 33 | B40: (Innen-)Ausbauberufe | D40: 1.1743203 | E40: 1028 | F40: 1005 | G40: 1042 | H40: 1095 | I40: 1067 | J40: -39 | K40: -3.6551078
A41: 34 | B41: Gebäude- u. versorgungstechnische Berufe | D41: 3.093443 | E41: 2708 | F41: 2662 | G41: 2690 | H41: 2724 | I41: 2719 | J41: -11 | K41: -0.4045605
A42: 41 | B42: Mathematik-Biologie-Chemie-,Physikberufe | D42: 0.75622573 | E42: 662 | F42: 668 | G42: 683 | H42: 699 | I42: 681 | J42: -19 | K42: -2.7900147
...

Sheet Tabelle 3.1
J1: Beschäftigungsstatistik
A3: 3.1 Geringfügig entlohnte Beschäftigte nach Regionen und ausgewählten Merkmalen
A4: ausgewählte Regionen; Gebietsstand des jeweiligen Stichtags
A5: Stichtag: 30. Juni 2025
A7: Regionen / Merkmale | C7: Anteile in % 1) | D7: geringfügig entlohnte Beschäftigte am Stichtag Ende ... | I7: Veränderung gegenüber dem Vorjahresstichtag (Spalte 1 zu Spalte 5)
D8: Jun. 25 | E8: Mrz. 25 | F8: Dez. 24 | G8: Sep. 24 | H8: Jun. 24
I9: absolut | J9: in %
D10: 1 | E10: 2 | F10: 3 | G10: 4 | H10: 5 | I10: 6 | J10: 7
A11: Görlitz (14626)
A12: Insgesamt | C12: 100 | D12: 11635 | E12: 11201 | F12: 11370 | G12: 11401 | H12: 11352 | I12: 283 | J12: 2.4929528
A13: dav. | B13: Männer | C13: 43.824667 | D13: 5099 | E13: 4899 | F13: 4922 | G13: 4931 | H13: 4926 | I13: 173 | J13: 3.5119773
B14: Frauen | C14: 56.175333 | D14: 6536 | E14: 6302 | F14: 6448 | G14: 6470 | H14: 6426 | I14: 110 | J14: 1.7117958
A15: dav. | B15: unter 25 Jahre | C15: 14.937688 | D15: 1738 | E15: 1471 | F15: 1483 | G15: 1532 | H15: 1608 | I15: 130 | J15: 8.0845771
B16: 25 bis unter 55 Jahre | C16: 36.106575 | D16: 4201 | E16: 4139 | F16: 4214 | G16: 4175 | H16: 4107 | I16: 94 | J16: 2.2887753
B17: 55 bis unter 65 Jahre | C17: 20.232058 | D17: 2354 | E17: 2364 | F17: 2391 | G17: 2418 | H17: 2437 | I17: -83 | J17: -3.4058268
B18: 65 Jahre und älter | C18: 28.723679 | D18: 3342 | E18: 3227 | F18: 3282 | G18: 3276 | H18: 3200 | I18: 142 | J18: 4.4375
B19: dar.: bis zur Altersgrenze | C19: 4.9505801 | D19: 576 | E19: 540 | F19: 500 | G19: 481 | H19: 464 | I19: 112 | J19: 24.137931
A20: dar. | B20: Deutsche | C20: 90.588741 | D20: 10540 | E20: 10189 | F20: 10354 | G20: 10345 | H20: 10328 | I20: 212 | J20: 2.0526723
B21: Ausländer | C21: 9.4112591 | D21: 1095 | E21: 1012 | F21: 1016 | G21: 1056 | H21: 1024 | I21: 71 | J21: 6.9335938
A22: Bundesland Sachsen
A23: Insgesamt | C23: 100 | D23: 233735 | E23: 228375 | F23: 232335 | G23: 231546 | H23: 231714 | I23: 2021 | J23: 0.8721959
A24: dav. | B24: Männer | C24: 46.285751 | D24: 108186 | E24: 105692 | F24: 106960 | G24: 106661 | H24: 106660 | I24: 1526 | J24: 1.4307144
B25: Frauen | C25: 53.714249 | D25: 125549 | E25: 122683 | F25: 125375 | G25: 124885 | H25: 125054 | I25: 495 | J25: 0.395829
A26: dav. | B26: unter 25 Jahre | C26: 20.495861 | D26: 47906 | E26: 44850 | F26: 46449 | G26: 46178 | H26: 47624 | I26: 282 | J26: 0.59213842
B27: 25 bis unter 55 Jahre | C27: 40.060753 | D27: 93636 | E27: 92507 | F27: 93611 | G27: 92814 | H27: 92085 | I27: 1551 | J27: 1.6843134
B28: 55 bis unter 65 Jahre | C28: 15.144073 | D28: 35397 | E28: 35322 | F28: 35727 | G28: 36134 | H28: 36213 | I28: -816 | J28: -2.2533344
B29: 65 Jahre und älter | C29: 24.298885 | D29: 56795 | E29: 55695 | F29: 56548 | G29: 56420 | H29: 55792 | I29: 1003 | J29: 1.7977488
B30: dar.: bis zur Altersgrenze | C30: 3.6712516 | D30: 8581 | E30: 8581 | F30: 7529 | G30: 7625 | H30: 7344 | I30: 1237 | J30: 16.843682
A31: dar. | B31: Deutsche | C31: 90.796843 | D31: 212224 | E31: 207776 | F31: 211988 | G31: 211464 | H31: 211858 | I31: 366 | J31: 0.17275722
B32: Ausländer | C32: 9.2031574 | D32: 21511 | E32: 20599 | F32: 20347 | G32: 20082 | H32: 19856 | I32: 1655 | J32: 8.3350121
A33: Ostdeutschland
A34: Insgesamt | C34: 100 | D34: 917029 | E34: 892571 | F34: 904804 | G34: 905616 | H34: 907133 | I34: 9896 | J34: 1.0909095
A35: dav. | B35: Männer | C35: 46.651305 | D35: 427806 | E35: 416387 | F35: 421126 | G35: 422159 | H35: 421734 | I35: 6072 | J35: 1.4397701
B36: Frauen | C36: 53.348695 | D36: 489223 | E36: 476184 | F36: 483678 | G36: 483457 | H36: 485399 | I36: 3824 | J36: 0.7878055
A37: dav. | B37: unter 25 Jahre | C37: 19.922816 | D37: 182698 | E37: 170893 | F37: 175014 | G37: 175725 | H37: 181096 | I37: 1602 | J37: 0.88461369
B38: 25 bis unter 55 Jahre | C38: 42.363219 | D38: 388483 | E38: 381218 | F38: 385658 | G38: 384067 | H38: 382578 | I38: 5905 | J38: 1.5434761
B39: 55 bis unter 65 Jahre | C39: 15.660137 | D39: 143608 | E39: 143322 | F39: 144890 | G39: 146631 | H39: 147264 | I39: -3656 | J39: -2.4826163
B40: 65 Jahre und älter | C40: 22.05361 | D40: 202238 | E40: 197136 | F40: 199240 | G40: 199191 | H40: 196193 | I40: 6045 | J40: 3.0811497
B41: dar.: bis zur Altersgrenze | C41: 3.4025096 | D41: 31202 | E41: 30860 | F41: 26739 | G41: 27074 | H41: 26155 | I41: 5047 | J41: 19.296502
A42: dar. | B42: Deutsche | C42: 87.619476 | D42: 803496 | E42: 783394 | F42: 795003 | G42: 796951 | H42: 798956 | I42: 4540 | J42: 0.56824156
...

Sheet Tabelle 3.2
L1: Beschäftigungsstatistik
A3: 3.2 Geringfügig entlohnte Beschäftigte nach ausgewählten Merkmalen
A4: Görlitz (14626); Gebietsstand des jeweiligen Stichtags
A5: Stichtag: 30. Juni 2025
A7: Merkmale | E7: Anteile in % 1) | F7: geringfügig entlohnte Beschäftigte am Stichtag Ende ... | K7: Veränderung gegenüber dem Vorjahresstichtag (Spalte 1 zu Spalte 5)
F8: Jun. 25 | G8: Mrz. 25 | H8: Dez. 24 | I8: Sep. 24 | J8: Jun. 24
K9: absolut | L9: in %
F10: 1 | G10: 2 | H10: 3 | I10: 4 | J10: 5 | K10: 6 | L10: 7
A11: Insgesamt | E11: 100 | F11: 11635 | G11: 11201 | H11: 11370 | I11: 11401 | J11: 11352 | K11: 283 | L11: 2.4929528
A12: nach dem Geschlecht dav. Männer | E12: 43.824667 | F12: 5099 | G12: 4899 | H12: 4922 | I12: 4931 | J12: 4926 | K12: 173 | L12: 3.5119773
B13: Frauen | E13: 56.175333 | F13: 6536 | G13: 6302 | H13: 6448 | I13: 6470 | J13: 6426 | K13: 110 | L13: 1.7117958
A14: nach Altersgruppen und Geschlecht dav. unter 25 Jahre | E14: 14.937688 | F14: 1738 | G14: 1471 | H14: 1483 | I14: 1532 | J14: 1608 | K14: 130 | L14: 8.0845771
C15: Männer | E15: 40.218642 | F15: 699 | G15: 587 | H15: 573 | I15: 603 | J15: 650 | K15: 49 | L15: 7.5384615
C16: Frauen | E16: 59.781358 | F16: 1039 | G16: 884 | H16: 910 | I16: 929 | J16: 958 | K16: 81 | L16: 8.4551148
B17: 25 bis unter 55 Jahre | E17: 36.106575 | F17: 4201 | G17: 4139 | H17: 4214 | I17: 4175 | J17: 4107 | K17: 94 | L17: 2.2887753
C18: Männer | E18: 42.061414 | F18: 1767 | G18: 1724 | H18: 1725 | I18: 1709 | J18: 1682 | K18: 85 | L18: 5.0535077
C19: Frauen | E19: 57.938586 | F19: 2434 | G19: 2415 | H19: 2489 | I19: 2466 | J19: 2425 | K19: 9 | L19: 0.37113402
B20: 55 bis unter 65 Jahre | E20: 20.232058 | F20: 2354 | G20: 2364 | H20: 2391 | I20: 2418 | J20: 2437 | K20: -83 | L20: -3.4058268
C21: Männer | E21: 38.105353 | F21: 897 | G21: 914 | H21: 921 | I21: 924 | J21: 935 | K21: -38 | L21: -4.0641711
C22: Frauen | E22: 61.894647 | F22: 1457 | G22: 1450 | H22: 1470 | I22: 1494 | J22: 1502 | K22: -45 | L22: -2.9960053
B23: 65 Jahre und älter | E23: 28.723679 | F23: 3342 | G23: 3227 | H23: 3282 | I23: 3276 | J23: 3200 | K23: 142 | L23: 4.4375
C24: Männer | E24: 51.944943 | F24: 1736 | G24: 1674 | H24: 1703 | I24: 1695 | J24: 1659 | K24: 77 | L24: 4.6413502
C25: Frauen | E25: 48.055057 | F25: 1606 | G25: 1553 | H25: 1579 | I25: 1581 | J25: 1541 | K25: 65 | L25: 4.2180402
C26: dar. | D26: bis zur Altersgrenze | E26: 4.9505801 | F26: 576 | G26: 540 | H26: 500 | I26: 481 | J26: 464 | K26: 112 | L26: 24.137931
D27: Männer | E27: 46.354167 | F27: 267 | G27: 245 | H27: 229 | I27: 213 | J27: 208 | K27: 59 | L27: 28.365385
D28: Frauen | E28: 53.645833 | F28: 309 | G28: 295 | H28: 271 | I28: 268 | J28: 256 | K28: 53 | L28: 20.703125
A29: nach Nationalität und Geschlecht dar. Deutsche | E29: 90.588741 | F29: 10540 | G29: 10189 | H29: 10354 | I29: 10345 | J29: 10328 | K29: 212 | L29: 2.0526723
C30: Männer | E30: 44.079696 | F30: 4646 | G30: 4484 | H30: 4507 | I30: 4502 | J30: 4492 | K30: 154 | L30: 3.428317
C31: Frauen | E31: 55.920304 | F31: 5894 | G31: 5705 | H31: 5847 | I31: 5843 | J31: 5836 | K31: 58 | L31: 0.99383139
B32: Ausländer | E32: 9.4112591 | F32: 1095 | G32: 1012 | H32: 1016 | I32: 1056 | J32: 1024 | K32: 71 | L32: 6.9335938
C33: Männer | E33: 41.369863 | F33: 453 | G33: 415 | H33: 415 | I33: 429 | J33: 434 | K33: 19 | L33: 4.3778802
C34: Frauen | E34: 58.630137 | F34: 642 | G34: 597 | H34: 601 | I34: 627 | J34: 590 | K34: 52 | L34: 8.8135593
A35: nach dem Berufsabschluss und Geschlecht dav. ohne beruflichen Ausbildungsabschluss | E35: 13.433606 | F35: 1563 | G35: 1344 | H35: 1336 | I35: 1392 | J35: 1438 | K35: 125 | L35: 8.6926287
C36: Männer | E36: 42.866283 | F36: 670 | G36: 569 | H36: 548 | I36: 586 | J36: 619 | K36: 51 | L36: 8.2390953
C37: Frauen | E37: 57.133717 | F37: 893 | G37: 775 | H37: 788 | I37: 806 | J37: 819 | K37: 74 | L37: 9.035409
B38: mit anerkanntem Berufsabschluss 2) | E38: 64.933391 | F38: 7555 | G38: 7412 | H38: 7568 | I38: 7508 | J38: 7415 | K38: 140 | L38: 1.8880647
C39: Männer | E39: 43.878226 | F39: 3315 | G39: 3240 | H39: 3294 | I39: 3265 | J39: 3208 | K39: 107 | L39: 3.3354115
C40: Frauen | E40: 56.121774 | F40: 4240 | G40: 4172 | H40: 4274 | I40: 4243 | J40: 4207 | K40: 33 | L40: 0.78440694
B41: mit akademischem Abschluss 3) | E41: 10.855178 | F41: 1263 | G41: 1224 | H41: 1201 | I41: 1212 | J41: 1189 | K41: 74 | L41: 6.2237174
C42: Männer | E42: 43.863816 | F42: 554 | G42: 548 | H42: 539 | I42: 542 | J42: 536 | K42: 18 | L42: 3.358209
...

Sheet Tabelle 3.3
J1: Beschäftigungsstatistik
A3: 3.3 Geringfügig entlohnte Beschäftigte nach der Klassifikation der Wirtschaftszweige 2008 (WZ 2008)
A4: Görlitz (14626); Gebietsstand des jeweiligen Stichtags
A5: Stichtag: 30. Juni 2025
A7: Wirtschaftsabschnitte / Wirtschaftsabteilungen / Wirtschaftsgruppen WZ 2008 | C7: Anteile in % 1) | D7: geringfügig entlohnte Beschäftigte am Stichtag Ende ... | I7: Veränderung gegenüber dem Vorjahresstichtag (Spalte 1 zu Spalte 5)
D8: Jun. 25 | E8: Mrz. 25 | F8: Dez. 24 | G8: Sep. 24 | H8: Jun. 24
I9: absolut | J9: in %
D10: 1 | E10: 2 | F10: 3 | G10: 4 | H10: 5 | I10: 6 | J10: 7
A11: Insgesamt | C11: 100 | D11: 11635 | E11: 11201 | F11: 11370 | G11: 11401 | H11: 11352 | I11: 283 | J11: 2.4929528
A12: A | B12: Land-, Forstwirtschaft und Fischerei | C12: 2.5870219 | D12: 301 | E12: 301 | F12: 331 | G12: 327 | H12: 323 | I12: -22 | J12: -6.8111455
A13: B,D,E | B13: Bergbau, Energie- und Wasserversorgung, Entsorgungswirtschaft | C13: 0.6617963 | D13: 77 | E13: 81 | F13: 78 | G13: 80 | H13: 89 | I13: -12 | J13: -13.483146
A14: C | B14: Verarbeitendes Gewerbe | C14: 8.0790718 | D14: 940 | E14: 907 | F14: 954 | G14: 935 | H14: 930 | I14: 10 | J14: 1.0752688
A15: dav. 10-15, 18, 21, 31 | B15: Herstellung von überwiegend häuslich konsumierten Gütern (ohne Güter der Metall-, Elektro- und Chemieindustrie) | C15: 3.9020198 | D15: 454 | E15: 410 | F15: 445 | G15: 442 | H15: 444 | I15: 10 | J15: 2.2522523
A16: 24-30, 32, 33 | B16: Metall- und Elektroindustrie sowie Stahlindustrie | C16: 3.2746025 | D16: 381 | E16: 383 | F16: 388 | G16: 385 | H16: 375 | I16: 6 | J16: 1.6
A17: 16, 17, 19, 20, ,22, 23 | B17: Hrst. v. Vorleistungsgütern, insb. v. chem. Erzeugnissen u. Kunststoffwaren (ohne Güter der Metall- u. Elektroindustrie) | C17: 0.90244951 | D17: 105 | E17: 114 | F17: 121 | G17: 108 | H17: 111 | I17: -6 | J17: -5.4054054
A18: F | B18: Baugewerbe | C18: 6.8758058 | D18: 800 | E18: 774 | F18: 793 | G18: 782 | H18: 770 | I18: 30 | J18: 3.8961039
A19: G | B19: Handel, Instandhaltung, Reparatur von Kfz | C19: 14.946283 | D19: 1739 | E19: 1674 | F19: 1690 | G19: 1662 | H19: 1691 | I19: 48 | J19: 2.8385571
A20: H | B20: Verkehr und Lagerei | C20: 4.5208423 | D20: 526 | E20: 515 | F20: 511 | G20: 533 | H20: 516 | I20: 10 | J20: 1.9379845
A21: I | B21: Gastgewerbe | C21: 14.387624 | D21: 1674 | E21: 1505 | F21: 1493 | G21: 1592 | H21: 1551 | I21: 123 | J21: 7.9303675
A22: J | B22: Information und Kommunikation | C22: 1.0399656 | D22: 121 | E22: 118 | F22: 130 | G22: 126 | H22: 122 | I22: -1 | J22: -0.81967213
A23: K | B23: Erbringung von Finanz- und Versicherungsdienstleistungen | C23: 1.5384615 | D23: 179 | E23: 172 | F23: 169 | G23: 162 | H23: 164 | I23: 15 | J23: 9.1463415
... A26: dav. N (ohne ANÜ) | B26: sonstige wirtschaftliche Dienstleistungen (ohne Arbeitnehmerüberlassung) | C26: 7.9157714 | D26: 921 | E26: 919 | F26: 942 | G26: 917 | H26: 911 | I26: 10 | J26: 1.0976948
A27: 782.783 | B27: Arbeitnehmerüberlassung | C27: 0.042973786 | D27: 5 | E27: 4 | F27: 3 | G27: 5 | H27: 6 | I27: -1 | J27: -16.666667
A28: O, U | B28: Öffentliche Verwaltung, Verteidigung, Sozialversicherung, Ext. Organisationen | C28: 2.088526 | D28: 243 | E28: 229 | F28: 230 | G28: 227 | H28: 225 | I28: 18 | J28: 8
A29: P | B29: Erziehung und Unterricht | C29: 2.5870219 | D29: 301 | E29: 300 | F29: 303 | G29: 297 | H29: 306 | I29: -5 | J29: -1.6339869
A30: 86 | B30: Gesundheitswesen | C30: 7.3571122 | D30: 856 | E30: 865 | F30: 869 | G30: 853 | H30: 825 | I30: 31 | J30: 3.7575758
A31: 87.88 | B31: Heime und Sozialwesen | C31: 5.0021487 | D31: 582 | E31: 575 | F31: 582 | G31: 566 | H31: 555 | I31: 27 | J31: 4.8648649
A32: R,S,T | B32: sonstige Dienstleistungen, Private Haushalte | C32: 11.749033 | D32: 1367 | E32: 1280 | F32: 1291 | G32: 1344 | H32: 1351 | I32: 16 | J32: 1.1843079
B33: keine Zuordnung möglich | C33: 0 | D33: 0 | E33: 0 | F33: 0 | G33: 0 | H33: 0 | I33: 0 | J33: 0
A34: davon nach Sektoren:
A35: A | B35: Land-, Forstwirtschaft und Fischerei | C35: 2.5870219 | D35: 301 | E35: 301 | F35: 331 | G35: 327 | H35: 323 | I35: -22 | J35: -6.8111455
A36: B - F | B36: Produzierendes Gewerbe | C36: 15.616674 | D36: 1817 | E36: 1762 | F36: 1825 | G36: 1797 | H36: 1789 | I36: 28 | J36: 1.5651202
A37: G - U | B37: Dienstleistungsbereich | C37: 81.796304 | D37: 9517 | E37: 9138 | F37: 9214 | G37: 9277 | H37: 9240 | I37: 277 | J37: 2.9978355
J38: © Statistik der Bundesagentur für Arbeit
A39: 1) Anteil an der jeweiligen Gesamtsumme (Spaltenprozent)
A40: *) Aus Datenschutzgründen und Gründen der statistischen Geheimhaltung werden Zahlenwerte von 1 oder 2 und Daten, aus denen rechnerisch auf einen solchen Zahlenwert geschlossen werden kann, anonymisiert. Gleiches gilt, wenn in einer Region weniger als 3 Betriebe ansässig sind oder einer der Betriebe einen so hohen Beschäftigtenanteil auf sich vereint, dass die Beschäftigtenzahl praktisch eine Einzelangabe über den Branchenführer darstellt (Dominanzfall).

Sheet Tabelle 3.4
K1: Beschäftigungsstatistik
A3: 3.4 Geringfügig entlohnte Beschäftigte nach der Klassifikation der Berufe (KldB 2010)
A4: Görlitz (14626); Gebietsstand des jeweiligen Stichtags
A5: Stichtag: 30. Juni 2025
A7: Anforderungsniveau/ Berufshauptgruppen/-gruppen (KldB2010) | D7: Anteile in % 1) | E7: geringfügig entlohnte Beschäftigte am Stichtag Ende ... | J7: Veränderung gegenüber dem Vorjahresstichtag (Spalte 1 zu Spalte 5)
E8: Jun. 25 | F8: Mrz. 25 | G8: Dez. 24 | H8: Sep. 24 | I8: Jun. 24
J9: absolut | K9: in %
E10: 1 | F10: 2 | G10: 3 | H10: 4 | I10: 5 | J10: 6 | K10: 7
A11: Insgesamt | D11: 100 | E11: 11635 | F11: 11201 | G11: 11370 | H11: 11401 | I11: 11352 | J11: 283 | K11: 2.4929528
A12: darunter nach Anforderungsniveau der ausgeübten Tätigkeit (KldB 2010)
A13: Helfer | D13: 43.154276 | E13: 5021 | F13: 4706 | G13: 4791 | H13: 4874 | I13: 4878 | J13: 143 | K13: 2.9315293
A14: Fachkraft | D14: 43.248818 | E14: 5032 | F14: 4920 | G14: 5033 | H14: 4994 | I14: 4947 | J14: 85 | K14: 1.7182131
A15: Spezialist | D15: 6.4718522 | E15: 753 | F15: 743 | G15: 723 | H15: 709 | I15: 681 | J15: 72 | K15: 10.572687
A16: Experte | D16: 4.5036528 | E16: 524 | F16: 532 | G16: 520 | H16: 510 | I16: 526 | J16: -2 | K16: -0.38022814
A17: darunter: ausgewählte Berufsaggregate2) nach der ausgeübten Tätigkeit (KldB 2010)
A18: Bauberufe | D18: 3.008165 | E18: 350 | F18: 331 | G18: 332 | H18: 344 | I18: 342 | J18: 8 | K18: 2.3391813
A19: Handwerksberufe | D19: 4.2544048 | E19: 495 | F19: 488 | G19: 495 | H19: 495 | I19: 481 | J19: 14 | K19: 2.9106029
A20: Ingenieure | D20: 0.5414697 | E20: 63 | F20: 61 | G20: 65 | H20: 69 | I20: 65 | J20: -2 | K20: -3.0769231
A21: MINT-Berufe | D21: 10.958315 | E21: 1275 | F21: 1276 | G21: 1317 | H21: 1305 | I21: 1293 | J21: -18 | K21: -1.3921114
A22: Pflegeberufe3) | D22: 2.3807477 | E22: 277 | F22: 278 | G22: 278 | H22: 275 | I22: 273 | J22: 4 | K22: 1.4652015
A23: davon nach Berufsfachlichkeit der ausgeübten Tätigkeit (KldB 2010)
A24: 11 | B24: Land-, Tier-, Forstwirtschaftsberufe | D24: 1.9338204 | E24: 225 | F24: 234 | G24: 263 | H24: 259 | I24: 260 | J24: -35 | K24: -13.461538
A25: dar. 111 | B25: Landwirtschaft | D25: 1.1602922 | E25: 135 | F25: 134 | G25: 157 | H25: 161 | I25: 153 | J25: -18 | K25: -11.764706
A26: 12 | B26: Gartenbauberufe, Floristik | D26: 1.2290503 | E26: 143 | F26: 129 | G26: 130 | H26: 136 | I26: 132 | J26: 11 | K26: 8.3333333
A27: 21 | B27: Rohstoffgewinn,Glas-,Keramikverarbeitung | D27: 0.12892136 | E27: 15 | F27: 16 | G27: 13 | H27: 14 | I27: 14 | J27: 1 | K27: 7.1428571
A28: 22 | B28: Kunststoff- u. Holzherst.,-verarbeitung | D28: 0.57584873 | E28: 67 | F28: 59 | G28: 56 | H28: 53 | I28: 56 | J28: 11 | K28: 19.642857
A29: 23 | B29: Papier-,Druckberufe, tech.Mediengestalt. | D29: 0.25784272 | E29: 30 | F29: 30 | G29: 30 | H29: 32 | I29: 36 | J29: -6 | K29: -16.666667
A30: 24 | B30: Metallerzeugung,-bearbeitung, Metallbau | D30: 0.97980232 | E30: 114 | F30: 110 | G30: 111 | H30: 110 | I30: 105 | J30: 9 | K30: 8.5714286
A31: 25 | B31: Maschinen- und Fahrzeugtechnikberufe | D31: 1.3064031 | E31: 152 | F31: 145 | G31: 134 | H31: 138 | I31: 141 | J31: 11 | K31: 7.8014184
A32: 26 | B32: Mechatronik-, Energie- u. Elektroberufe | D32: 0.93682853 | E32: 109 | F32: 102 | G32: 103 | H32: 100 | I32: 101 | J32: 8 | K32: 7.9207921
A33: 27 | B33: Techn.Entwickl.Konstr.Produktionssteuer. | D33: 0.4813064 | E33: 56 | F33: 61 | G33: 59 | H33: 58 | I33: 55 | J33: 1 | K33: 1.8181818
A34: 28 | B34: Textil- und Lederberufe | D34: 0.2406532 | E34: 28 | F34: 26 | G34: 30 | H34: 27 | I34: 27 | J34: 1 | K34: 3.7037037
A35: 29 | B35: Lebensmittelherstellung u. -verarbeitung | D35: 4.0481306 | E35: 471 | F35: 454 | G35: 434 | H35: 466 | I35: 450 | J35: 21 | K35: 4.6666667
A36: dar. 292 | B36: Lebensmittel- u. Genussmittelherstellung | D36: 0.71336485 | E36: 83 | F36: * | G36: * | H36: 76 | I36: * | J36: * | K36: *
A37: dar. 293 | B37: Speisenzubereitung | D37: 3.3089815 | E37: 385 | F37: 369 | G37: 355 | H37: 387 | I37: 373 | J37: 12 | K37: 3.2171582
A38: 31 | B38: Bauplanung,Architektur,Vermessungsberufe | D38: 0.26643747 | E38: 31 | F38: 30 | G38: 30 | H38: 31 | I38: 30 | J38: 1 | K38: 3.3333333
A39: 32 | B39: Hoch- und Tiefbauberufe | D39: 1.0313709 | E39: 120 | F39: 113 | G39: 122 | H39: 126 | I39: 131 | J39: -11 | K39: -8.3969466
A40: 33 | B40: (Innen-)Ausbauberufe | D40: 0.78212291 | E40: 91 | F40: 81 | G40: 79 | H40: 83 | I40: 86 | J40: 5 | K40: 5.8139535
A41: 34 | B41: Gebäude- u. versorgungstechnische Berufe | D41: 7.1250537 | E41: 829 | F41: 836 | G41: 867 | H41: 854 | I41: 847 | J41: -18 | K41: -2.1251476
A42: 41 | B42: Mathematik-Biologie-Chemie-,Physikberufe | D42: 0.19767942 | E42: 23 | F42: 23 | G42: 24 | H42: 25 | I42: 19 | J42: 4 | K42: 21.052632
...

Sheet Tabelle 4.1
L1: Beschäftigungsstatistik
A3: 4.1 Begonnene sozialversicherungspflichtige Beschäftigungsverhältnisse und darunter befristete Beschäftigungsverhältnisse sowie Befristungsanteile nach ausgewählten Merkmalen
A4: Görlitz (14626); Gebietsstand des jeweiligen Stichtags
A5: 2. Quartal 2025
A7: Merkmale | F7: Insgesamt
F8: 2. Quartal 2025 | G8: 1. Quartal 2025 | H8: 4. Quartal 2024 | I8: 3. Quartal 2024 | J8: 2. Quartal 2024 | K8: Veränderung gegenüber dem Vorjahresquartal (Spalte 1 zu Spalte 5)
K9: absolut | L9: in %(-Pkt.)
F10: 1 | G10: 2 | H10: 3 | I10: 4 | J10: 5 | K10: 6 | L10: 7
A11: begonnene sozialversicherungspflichtige Beschäftigungsverhältnisse (begBV)
A12: Insgesamt | F12: 4822 | G12: 5180 | H12: 3451 | I12: 6212 | J12: 4313 | K12: 509 | L12: 11.80153
A13: dav.: | B13: Männer | F13: 2723 | G13: 2722 | H13: 1760 | I13: 3278 | J13: 2323 | K13: 400 | L13: 17.219113
B14: Frauen | F14: 2099 | G14: 2458 | H14: 1691 | I14: 2934 | J14: 1990 | K14: 109 | L14: 5.4773869
A15: dar.: | B15: unter 25 Jahre | F15: 895 | G15: 919 | H15: 684 | I15: 2582 | J15: 735 | K15: 160 | L15: 21.768707
B16: 25 bis unter 55 Jahre | F16: 3105 | G16: 3338 | H16: 2300 | I16: 2994 | J16: 2902 | K16: 203 | L16: 6.9951757
B17: 55 bis unter 65 Jahre | F17: 737 | G17: 831 | H17: 418 | I17: 563 | J17: 605 | K17: 132 | L17: 21.818182
B18: 65 Jahre und älter | F18: 85 | G18: 92 | H18: 49 | I18: 73 | J18: 71 | K18: 14 | L18: 19.71831
A19: dar. | B19: in Vollzeit | F19: 2736 | G19: 2980 | H19: 1769 | I19: 3994 | J19: 2342 | K19: 394 | L19: 16.823228
B20: in Teilzeit | F20: 2086 | G20: 2200 | H20: 1682 | I20: 2218 | J20: 1971 | K20: 115 | L20: 5.8346017
A21: dar. | B21: Deutsche | F21: 3488 | G21: 3936 | H21: 2533 | I21: 4861 | J21: 3148 | K21: 340 | L21: 10.800508
B22: Ausländer | F22: 1334 | G22: 1244 | H22: 918 | I22: 1351 | J22: 1165 | K22: 169 | L22: 14.506438
A23: dar.: | B23: Auszubildende | F23: 85 | G23: 96 | H23: 102 | I23: 1227 | J23: 33 | K23: 52 | L23: 157.57576
A24: Befristungsanteil 2)
A25: Insgesamt | F25: 35 | G25: 31.8 | H25: 35.2 | I25: 37.5 | J25: 36.4 | K25: x | L25: -1.4
A26: dav. | B26: Männer | F26: 31.1 | G26: 30.1 | H26: 30.5 | I26: 32.8 | J26: 31.1 | K26: x | L26: 0
B27: Frauen | F27: 40.2 | G27: 33.6 | H27: 40 | I27: 42.6 | J27: 42.6 | K27: x | L27: -2.4
A28: dar. | B28: unter 25 Jahre | F28: 50.2 | G28: 41.8 | H28: 41.6 | I28: 45.7 | J28: 49.3 | K28: x | L28: 0.9
B29: 25 bis unter 55 Jahre | F29: 32.5 | G29: 31.2 | H29: 34.6 | I29: 34.8 | J29: 34.2 | K29: x | L29: -1.7
B30: 55 bis unter 65 Jahre | F30: 27.7 | G30: 25.3 | H30: 29.5 | I30: 33.9 | J30: 30.6 | K30: x | L30: -2.9
B31: 65 Jahre und älter | F31: 43.5 | G31: 26.7 | H31: 38.8 | I31: 43.8 | J31: 49.3 | K31: x | L31: -5.8
A32: dar. | B32: in Vollzeit | F32: 29.6 | G32: 30 | H32: 27.4 | I32: 30.7 | J32: 30.1 | K32: x | L32: -0.5
B33: in Teilzeit | F33: 42.1 | G33: 34.1 | H33: 43 | I33: 46.1 | J33: 43.9 | K33: x | L33: -1.8
A34: dar. | B34: Deutsche | F34: 31.6 | G34: 28.3 | H34: 35.8 | I34: 37.3 | J34: 33.6 | K34: x | L34: -2
B35: Ausländer | F35: 43.9 | G35: 42.7 | H35: 33.5 | I35: 38.2 | J35: 43.8 | K35: x | L35: 0.1
A36: dar.: beg. svpfl. BV in der SvB-Kerngruppe 3) | F36: 4691 | G36: 5000 | H36: 3271 | I36: 4709 | J36: 4232 | K36: 459 | L36: 10.845936
B37: dar. | C37: befristet | F37: 1644 | G37: 1589 | H37: 1151 | I37: 1768 | J37: 1541 | K37: 103 | L37: 6.6839714
B38: dav. | C38: Männer | F38: 2645 | G38: 2627 | H38: 1649 | I38: 2432 | J38: 2285 | K38: 360 | L38: 15.754923
C39: dar. befristet | F39: 822 | G39: 791 | H39: 503 | I39: 797 | J39: 711 | K39: 111 | L39: 15.611814
C40: Frauen | F40: 2046 | G40: 2373 | H40: 1622 | I40: 2277 | J40: 1947 | K40: 99 | L40: 5.0847458
C41: dar. befristet | F41: 822 | G41: 798 | H41: 648 | I41: 971 | J41: 830 | K41: -8 | L41: -0.96385542
B42: dar. | C42: unter 25 Jahren | F42: 812 | G42: 775 | H42: 536 | I42: 1177 | J42: 692 | K42: 120 | L42: 17.34104
...

Sheet Tabelle 4.2
J1: Beschäftigungsstatistik
A3: 4.2 Begonnene sozialversicherungspflichtige Beschäftigungsverhältnisse nach der Klassifikation der Wirtschaftszweige 2008 (WZ 2008)
A4: Görlitz (14626); Gebietsstand des jeweiligen Stichtags
A5: 2. Quartal 2025
A7: Wirtschaftsabschnitte / Wirtschaftsabteilungen / Wirtschaftsgruppen WZ 2008 | C7: Anteile in % 1) | D7: begonnene sozialversicherungspflichtige Beschäftigungsverhältnisse2) im… | I7: Veränderung gegenüber dem Vorjahresquartal (Spalte 1 zu Spalte 5)
D8: 2. Quartal 2025 | E8: 1. Quartal 2025 | F8: 4. Quartal 2024 | G8: 3. Quartal 2024 | H8: 2. Quartal 2024
I9: absolut | J9: in %
D10: 1 | E10: 2 | F10: 3 | G10: 4 | H10: 5 | I10: 6 | J10: 7
A11: Insgesamt | C11: 100 | D11: 4822 | E11: 5180 | F11: 3451 | G11: 6212 | H11: 4313 | I11: 509 | J11: 11.80153
A12: A | B12: Land-, Forstwirtschaft und Fischerei | C12: 1.907922 | D12: 92 | E12: 134 | F12: 62 | G12: 137 | H12: 113 | I12: -21 | J12: -18.584071
A13: B,D,E | B13: Bergbau, Energie- und Wasserversorgung, Entsorgungswirtschaft | C13: 1.9286603 | D13: 93 | E13: 84 | F13: 68 | G13: 119 | H13: 149 | I13: -56 | J13: -37.583893
A14: C | B14: Verarbeitendes Gewerbe | C14: 20.468685 | D14: 987 | E14: 1124 | F14: 489 | G14: 1074 | H14: 713 | I14: 274 | J14: 38.429173
A15: dav. 10-15, 18, 21, 31 | B15: Herstellung von überwiegend häuslich konsumierten Gütern (ohne Güter der Metall-, Elektro- und Chemieindustrie) | C15: 10.38988 | D15: 501 | E15: 412 | F15: 189 | G15: 356 | H15: 321 | I15: 180 | J15: 56.074766
A16: 24-30, 32, 33 | B16: Metall- und Elektroindustrie sowie Stahlindustrie | C16: 7.3828287 | D16: 356 | E16: 570 | F16: 216 | G16: 478 | H16: 241 | I16: 115 | J16: 47.717842
A17: 16, 17, 19, 20, ,22, 23 | B17: Hrst. v. Vorleistungsgütern, insb. v. chem. Erzeugnissen u. Kunststoffwaren (ohne Güter der Metall- u. Elektroindustrie) | C17: 2.6959768 | D17: 130 | E17: 142 | F17: 84 | G17: 240 | H17: 151 | I17: -21 | J17: -13.907285
A18: F | B18: Baugewerbe | C18: 7.2998756 | D18: 352 | E18: 343 | F18: 141 | G18: 419 | H18: 282 | I18: 70 | J18: 24.822695
A19: G | B19: Handel, Instandhaltung, Reparatur von Kfz | C19: 11.074243 | D19: 534 | E19: 549 | F19: 420 | G19: 726 | H19: 462 | I19: 72 | J19: 15.584416
A20: H | B20: Verkehr und Lagerei | C20: 3.6291995 | D20: 175 | E20: 218 | F20: 176 | G20: 202 | H20: 217 | I20: -42 | J20: -19.354839
A21: I | B21: Gastgewerbe | C21: 9.4981336 | D21: 458 | E21: 313 | F21: 199 | G21: 282 | H21: 395 | I21: 63 | J21: 15.949367
A22: J | B22: Information und Kommunikation | C22: 0.82953131 | D22: 40 | E22: 57 | F22: 37 | G22: 46 | H22: 27 | I22: 13 | J22: 48.148148
A23: K | B23: Erbringung von Finanz- und Versicherungsdienstleistungen | C23: 0.89174616 | D23: 43 | E23: 36 | F23: 41 | G23: 47 | H23: 29 | I23: 14 | J23: 48.275862
... A26: dav. N (ohne ANÜ) | B26: sonstige wirtschaftliche Dienstleistungen (ohne Arbeitnehmerüberlassung) | C26: 7.6109498 | D26: 367 | E26: 302 | F26: 243 | G26: 300 | H26: 345 | I26: 22 | J26: 6.3768116
A27: 782.783 | B27: Arbeitnehmerüberlassung | C27: 4.5624222 | D27: 220 | E27: 183 | F27: 242 | G27: 327 | H27: 176 | I27: 44 | J27: 25
A28: O, U | B28: Öffentliche Verwaltung, Verteidigung, Sozialversicherung, Ext. Organisationen | C28: 2.861883 | D28: 138 | E28: 187 | F28: 117 | G28: 253 | H28: 143 | I28: -5 | J28: -3.4965035
A29: P | B29: Erziehung und Unterricht | C29: 2.3019494 | D29: 111 | E29: 179 | F29: 142 | G29: 309 | H29: 109 | I29: 2 | J29: 1.8348624
A30: 86 | B30: Gesundheitswesen | C30: 5.0808793 | D30: 245 | E30: 315 | F30: 191 | G30: 508 | H30: 215 | I30: 30 | J30: 13.953488
A31: 87.88 | B31: Heime und Sozialwesen | C31: 10.223973 | D31: 493 | E31: 577 | F31: 483 | G31: 758 | H31: 404 | I31: 89 | J31: 22.029703
A32: R,S,T | B32: sonstige Dienstleistungen, Private Haushalte | C32: 5.5578598 | D32: 268 | E32: 289 | F32: 239 | G32: 379 | H32: 315 | I32: -47 | J32: -14.920635
B33: keine Zuordnung möglich | C33: 0 | D33: 0 | E33: 0 | F33: 0 | G33: 0 | H33: 0 | I33: 0 | J33: 0
A34: davon nach Sektoren:
A35: A | B35: Land-, Forstwirtschaft und Fischerei | C35: 1.907922 | D35: 92 | E35: 134 | F35: 62 | G35: 137 | H35: 113 | I35: -21 | J35: -18.584071
A36: B - F | B36: Produzierendes Gewerbe | C36: 29.697221 | D36: 1432 | E36: 1551 | F36: 698 | G36: 1612 | H36: 1144 | I36: 288 | J36: 25.174825
A37: G - U | B37: Dienstleistungsbereich | C37: 68.394857 | D37: 3298 | E37: 3495 | F37: 2691 | G37: 4463 | H37: 3056 | I37: 242 | J37: 7.9188482
J38: © Statistik der Bundesagentur für Arbeit
A39: 1) Anteil an der jeweiligen Gesamtsumme (Spaltenprozent)
A40: 2) Als begonnene Beschäftigungsverhältnisse im Sinne der Beschäftigungsstatistik zählen die Anmeldungen zu einem sozialversicherungspflichtigen Beschäftigungsverhältnis innerhalb eines Zeitraums. Mehrfacherfassungen von Beschäftigten sind möglich.
A41: *) Aus Datenschutzgründen und Gründen der statistischen Geheimhaltung werden Zahlenwerte von 1 oder 2 und Daten, aus denen rechnerisch auf einen solchen Zahlenwert geschlossen werden kann, anonymisiert. Gleiches gilt, wenn eine Region oder ein Wirtschaftszweig 1 oder 2 Betriebe aufweist oder einer der Betriebe einen so hohen Beschäftigtenanteil auf sich vereint, dass die Beschäftigtenzahl praktisch eine Einzelangabe über diesen Betrieb darstellt (Dominanzfall). In Fällen, in denen Werte von Null eine Information über den Merkmalsträger offen legen, werden auch diese Nullwerte anonymisiert.

Sheet Tabelle 4.3
K1: Beschäftigungsstatistik
A3: 4.3 Begonnene sozialversicherungspflichtige Beschäftigungsverhältnisse nach der Klassifikation der Berufe (KldB 2010)
A4: Görlitz (14626); Gebietsstand des jeweiligen Stichtags
A5: 2. Quartal 2025
A7: Anforderungsniveau/ Berufshauptgruppen/-gruppen (KldB2010) | D7: Anteile in % 1) | E7: begonnene sozialversicherungspflichtige Beschäftigungsverhältnisse3) im… | J7: Veränderung gegenüber dem Vorjahresquartal (Spalte 1 zu Spalte 5)
E8: 2. Quartal 2025 | F8: 1. Quartal 2025 | G8: 4. Quartal 2024 | H8: 3. Quartal 2024 | I8: 2. Quartal 2024
J9: absolut | K9: in %
E10: 1 | F10: 2 | G10: 3 | H10: 4 | I10: 5 | J10: 6 | K10: 7
A11: Insgesamt | D11: 100 | E11: 4822 | F11: 5180 | G11: 3451 | H11: 6212 | I11: 4313 | J11: 509 | K11: 11.80153
A12: darunter nach Anforderungsniveau der ausgeübten Tätigkeit (KldB 2010)
A13: Helfer | D13: 29.220241 | E13: 1409 | F13: 1392 | G13: 993 | H13: 1529 | I13: 1255 | J13: 154 | K13: 12.270916
A14: Fachkraft | D14: 55.827457 | E14: 2692 | F14: 2809 | G14: 1781 | H14: 3679 | I14: 2393 | J14: 299 | K14: 12.494776
A15: Spezialist | D15: 7.6109498 | E15: 367 | F15: 489 | G15: 290 | H15: 467 | I15: 326 | J15: 41 | K15: 12.576687
